<sdf version='1.6'>
  <model name='iiwa14'>
  <pose frame=''>0 0 5 0 -0 0</pose>
    <link name='iiwa_link_0'>
      <pose frame=''>0 0 0 0 -0 0</pose>
      <inertial>
        <pose frame=''>-0.1 0 0.07 0 -0 0</pose>
        <mass>5</mass>
        <inertia>
          <ixx>0.05</ixx>
          <ixy>0</ixy>
          <ixz>0</ixz>
          <iyy>0.06</iyy>
          <iyz>0</iyz>
          <izz>0.03</izz>
        </inertia>
      </inertial>
      <collision name='iiwa_link_0_collision'>
        <pose frame=''>0 0 0 0 -0 0</pose>
        <geometry>
          <mesh>
            <scale>1 1 1</scale>
            <uri>model://kuka_robot_with_smaller_gripper/meshes/collision/link_0.dae</uri>
          </mesh>
        </geometry>
        <surface>
          <contact>
            <ode/>
          </contact>
          <friction>
            <ode>
              <mu>0.2</mu>
              <mu2>0.2</mu2>
            </ode>
          </friction>
        </surface>
      </collision>
      <visual name='iiwa_link_0_visual'>
        <pose frame=''>0 0 0 0 -0 0</pose>
        <geometry>
          <mesh>
            <scale>1 1 1</scale>
            <uri>model://kuka_robot_with_smaller_gripper/meshes/visual/link_0.dae</uri>
          </mesh>
        </geometry>
        <material>
          <script>
            <name>Gazebo/Grey</name>
            <uri>file://media/materials/scripts/gazebo.material</uri>
          </script>
        </material>
      </visual>
      <gravity>1</gravity>
      <velocity_decay/>
    </link>
    <joint name='world_iiwa_joint' type='fixed'>
      <child>iiwa_link_0</child>
      <parent>world</parent>
    </joint>
    <link name='iiwa_link_1'>
      <pose frame=''>0 0 0.1575 0 -0 0</pose>
      <inertial>
        <pose frame=''>0 -0.03 0.12 0 -0 0</pose>
        <mass>4</mass>
        <inertia>
          <ixx>0.1</ixx>
          <ixy>0</ixy>
          <ixz>0</ixz>
          <iyy>0.09</iyy>
          <iyz>0</iyz>
          <izz>0.02</izz>
        </inertia>
      </inertial>
      <collision name='iiwa_link_1_collision'>
        <pose frame=''>0 0 0 0 -0 0</pose>
        <geometry>
          <mesh>
            <scale>1 1 1</scale>
            <uri>model://kuka_robot_with_smaller_gripper/meshes/collision/link_1.dae</uri>
          </mesh>
        </geometry>
        <surface>
          <contact>
            <ode/>
          </contact>
          <friction>
            <ode>
              <mu>0.2</mu>
              <mu2>0.2</mu2>
            </ode>
          </friction>
        </surface>
      </collision>
      <visual name='iiwa_link_1_visual'>
        <pose frame=''>0 0 0 0 -0 0</pose>
        <geometry>
          <mesh>
            <scale>1 1 1</scale>
            <uri>model://kuka_robot_with_smaller_gripper/meshes/visual/link_1.dae</uri>
          </mesh>
        </geometry>
        <material>
          <script>
            <name>Gazebo/Orange</name>
            <uri>file://media/materials/scripts/gazebo.material</uri>
          </script>
        </material>
      </visual>
      <gravity>1</gravity>
      <velocity_decay/>
    </link>
    <joint name='iiwa_joint_1' type='revolute'>
      <child>iiwa_link_1</child>
      <parent>iiwa_link_0</parent>
      <axis>
        <xyz>0 0 1</xyz>
        <limit>
          <lower>-2.96706</lower>
          <upper>2.96706</upper>
          <effort>300</effort>
          <velocity>10</velocity>
        </limit>
        <dynamics>
          <damping>0.5</damping>
          <friction>0</friction>
          <spring_reference>0</spring_reference>
          <spring_stiffness>0</spring_stiffness>
        </dynamics>
        <use_parent_model_frame>1</use_parent_model_frame>
      </axis>
    </joint>
    <link name='iiwa_link_2'>
      <pose frame=''>0 0 0.36 1.5708 -0 -3.14159</pose>
      <inertial>
        <pose frame=''>0.0003 0.059 0.042 0 -0 0</pose>
        <mass>0.4</mass>
        <inertia>
          <ixx>0.005</ixx>
          <ixy>0</ixy>
          <ixz>0</ixz>
          <iyy>0.0018</iyy>
          <iyz>0</iyz>
          <izz>0.0044</izz>
        </inertia>
      </inertial>
      <collision name='iiwa_link_2_collision'>
        <pose frame=''>0 0 0 0 -0 0</pose>
        <geometry>
          <mesh>
            <scale>1 1 1</scale>
            <uri>model://kuka_robot_with_smaller_gripper/meshes/collision/link_2.dae</uri>
          </mesh>
        </geometry>
        <surface>
          <contact>
            <ode/>
          </contact>
          <friction>
            <ode>
              <mu>0.2</mu>
              <mu2>0.2</mu2>
            </ode>
          </friction>
        </surface>
      </collision>
      <visual name='iiwa_link_2_visual'>
        <pose frame=''>0 0 0 0 -0 0</pose>
        <geometry>
          <mesh>
            <scale>1 1 1</scale>
            <uri>model://kuka_robot_with_smaller_gripper/meshes/visual/link_2.dae</uri>
          </mesh>
        </geometry>
        <material>
          <script>
            <name>Gazebo/Orange</name>
            <uri>file://media/materials/scripts/gazebo.material</uri>
          </script>
        </material>
      </visual>
      <gravity>1</gravity>
      <velocity_decay/>
    </link>
    <joint name='iiwa_joint_2' type='revolute'>
      <child>iiwa_link_2</child>
      <parent>iiwa_link_1</parent>
      <axis>
        <xyz>-0 1 0</xyz>
        <limit>
          <lower>-2.0944</lower>
          <upper>2.0944</upper>
          <effort>300</effort>
          <velocity>10</velocity>
        </limit>
        <dynamics>
          <damping>0.5</damping>
          <friction>0</friction>
          <spring_reference>0</spring_reference>
          <spring_stiffness>0</spring_stiffness>
        </dynamics>
        <use_parent_model_frame>1</use_parent_model_frame>
      </axis>
    </joint>
    <link name='iiwa_link_3'>
      <pose frame=''>0 -0 0.5645 0 0 0</pose>
      <inertial>
        <pose frame=''>0 0.03 0.13 0 -0 0</pose>
        <mass>0.3</mass>
        <inertia>
          <ixx>0.008</ixx>
          <ixy>0</ixy>
          <ixz>0</ixz>
          <iyy>0.0075</iyy>
          <iyz>0</iyz>
          <izz>0.001</izz>
        </inertia>
      </inertial>
      <collision name='iiwa_link_3_collision'>
        <pose frame=''>0 0 0 0 -0 0</pose>
        <geometry>
          <mesh>
            <scale>1 1 1</scale>
            <uri>model://kuka_robot_with_smaller_gripper/meshes/collision/link_3.dae</uri>
          </mesh>
        </geometry>
        <surface>
          <contact>
            <ode/>
          </contact>
          <friction>
            <ode>
              <mu>0.2</mu>
              <mu2>0.2</mu2>
            </ode>
          </friction>
        </surface>
      </collision>
      <visual name='iiwa_link_3_visual'>
        <pose frame=''>0 0 0 0 -0 0</pose>
        <geometry>
          <mesh>
            <scale>1 1 1</scale>
            <uri>model://kuka_robot_with_smaller_gripper/meshes/visual/link_3.dae</uri>
          </mesh>
        </geometry>
        <material>
          <script>
            <name>Gazebo/Orange</name>
            <uri>file://media/materials/scripts/gazebo.material</uri>
          </script>
        </material>
      </visual>
      <gravity>1</gravity>
      <velocity_decay/>
    </link>
    <joint name='iiwa_joint_3' type='revolute'>
      <child>iiwa_link_3</child>
      <parent>iiwa_link_2</parent>
      <axis>
        <xyz>0 0 1</xyz>
        <limit>
          <lower>-2.96706</lower>
          <upper>2.96706</upper>
          <effort>300</effort>
          <velocity>10</velocity>
        </limit>
        <dynamics>
          <damping>0.5</damping>
          <friction>0</friction>
          <spring_reference>0</spring_reference>
          <spring_stiffness>0</spring_stiffness>
        </dynamics>
        <use_parent_model_frame>1</use_parent_model_frame>
      </axis>
    </joint>
    <link name='iiwa_link_4'>
      <pose frame=''>0 -0 0.78 1.5708 0 0</pose>
      <inertial>
        <pose frame=''>0 0.067 0.034 0 -0 0</pose>
        <mass>0.27</mass>
        <inertia>
          <ixx>0.003</ixx>
          <ixy>0</ixy>
          <ixz>0</ixz>
          <iyy>0.001</iyy>
          <iyz>0</iyz>
          <izz>0.0029</izz>
        </inertia>
      </inertial>
      <collision name='iiwa_link_4_collision'>
        <pose frame=''>0 0 0 0 -0 0</pose>
        <geometry>
          <mesh>
            <scale>1 1 1</scale>
            <uri>model://kuka_robot_with_smaller_gripper/meshes/collision/link_4.dae</uri>
          </mesh>
        </geometry>
        <surface>
          <contact>
            <ode/>
          </contact>
          <friction>
            <ode>
              <mu>0.2</mu>
              <mu2>0.2</mu2>
            </ode>
          </friction>
        </surface>
      </collision>
      <visual name='iiwa_link_4_visual'>
        <pose frame=''>0 0 0 0 -0 0</pose>
        <geometry>
          <mesh>
            <scale>1 1 1</scale>
            <uri>model://kuka_robot_with_smaller_gripper/meshes/visual/link_4.dae</uri>
          </mesh>
        </geometry>
        <material>
          <script>
            <name>Gazebo/Orange</name>
            <uri>file://media/materials/scripts/gazebo.material</uri>
          </script>
        </material>
      </visual>
      <gravity>1</gravity>
      <velocity_decay/>
    </link>
    <joint name='iiwa_joint_4' type='revolute'>
      <child>iiwa_link_4</child>
      <parent>iiwa_link_3</parent>
      <axis>
        <xyz>0 -1 0</xyz>
        <limit>
          <lower>-2.0944</lower>
          <upper>2.0944</upper>
          <effort>300</effort>
          <velocity>10</velocity>
        </limit>
        <dynamics>
          <damping>0.5</damping>
          <friction>0</friction>
          <spring_reference>0</spring_reference>
          <spring_stiffness>0</spring_stiffness>
        </dynamics>
        <use_parent_model_frame>1</use_parent_model_frame>
      </axis>
    </joint>
    <link name='iiwa_link_5'>
      <pose frame=''>0 -0 0.9645 0 -0 -3.14159</pose>
      <inertial>
        <pose frame=''>0.0001 0.021 0.076 0 -0 0</pose>
        <mass>0.17</mass>
        <inertia>
          <ixx>0.002</ixx>
          <ixy>0</ixy>
          <ixz>0</ixz>
          <iyy>0.0018</iyy>
          <iyz>0</iyz>
          <izz>0.0005</izz>
        </inertia>
      </inertial>
      <collision name='iiwa_link_5_collision'>
        <pose frame=''>0 0 0 0 -0 0</pose>
        <geometry>
          <mesh>
            <scale>1 1 1</scale>
            <uri>model://kuka_robot_with_smaller_gripper/meshes/collision/link_5.dae</uri>
          </mesh>
        </geometry>
        <surface>
          <contact>
            <ode/>
          </contact>
          <friction>
            <ode>
              <mu>0.2</mu>
              <mu2>0.2</mu2>
            </ode>
          </friction>
        </surface>
      </collision>
      <visual name='iiwa_link_5_visual'>
        <pose frame=''>0 0 0 0 -0 0</pose>
        <geometry>
          <mesh>
            <scale>1 1 1</scale>
            <uri>model://kuka_robot_with_smaller_gripper/meshes/visual/link_5.dae</uri>
          </mesh>
        </geometry>
        <material>
          <script>
            <name>Gazebo/Orange</name>
            <uri>file://media/materials/scripts/gazebo.material</uri>
          </script>
        </material>
      </visual>
      <gravity>1</gravity>
      <velocity_decay/>
    </link>
    <joint name='iiwa_joint_5' type='revolute'>
      <child>iiwa_link_5</child>
      <parent>iiwa_link_4</parent>
      <axis>
        <xyz>0 0 1</xyz>
        <limit>
          <lower>-2.96706</lower>
          <upper>2.96706</upper>
          <effort>300</effort>
          <velocity>10</velocity>
        </limit>
        <dynamics>
          <damping>0.5</damping>
          <friction>0</friction>
          <spring_reference>0</spring_reference>
          <spring_stiffness>0</spring_stiffness>
        </dynamics>
        <use_parent_model_frame>1</use_parent_model_frame>
      </axis>
    </joint>
    <link name='iiwa_link_6'>
      <pose frame=''>0 0 1.18 1.5708 -0 -3.14159</pose>
      <inertial>
        <pose frame=''>0 0.0006 0.0004 0 -0 0</pose>
        <mass>0.18</mass>
        <inertia>
          <ixx>0.0005</ixx>
          <ixy>0</ixy>
          <ixz>0</ixz>
          <iyy>0.00036</iyy>
          <iyz>0</iyz>
          <izz>0.00047</izz>
        </inertia>
      </inertial>
      <collision name='iiwa_link_6_collision'>
        <pose frame=''>0 0 0 0 -0 0</pose>
        <geometry>
          <mesh>
            <scale>1 1 1</scale>
            <uri>model://kuka_robot_with_smaller_gripper/meshes/collision/link_6.dae</uri>
          </mesh>
        </geometry>
        <surface>
          <contact>
            <ode/>
          </contact>
          <friction>
            <ode>
              <mu>0.2</mu>
              <mu2>0.2</mu2>
            </ode>
          </friction>
        </surface>
      </collision>
      <visual name='iiwa_link_6_visual'>
        <pose frame=''>0 0 0 0 -0 0</pose>
        <geometry>
          <mesh>
            <scale>1 1 1</scale>
            <uri>model://kuka_robot_with_smaller_gripper/meshes/visual/link_6.dae</uri>
          </mesh>
        </geometry>
        <material>
          <script>
            <name>Gazebo/Orange</name>
            <uri>file://media/materials/scripts/gazebo.material</uri>
          </script>
        </material>
      </visual>
      <gravity>1</gravity>
      <velocity_decay/>
    </link>
    <joint name='iiwa_joint_6' type='revolute'>
      <child>iiwa_link_6</child>
      <parent>iiwa_link_5</parent>
      <axis>
        <xyz>-0 1 -0</xyz>
        <limit>
          <lower>-2.0944</lower>
          <upper>2.0944</upper>
          <effort>300</effort>
          <velocity>10</velocity>
        </limit>
        <dynamics>
          <damping>0.5</damping>
          <friction>0</friction>
          <spring_reference>0</spring_reference>
          <spring_stiffness>0</spring_stiffness>
        </dynamics>
        <use_parent_model_frame>1</use_parent_model_frame>
      </axis>
    </joint>
    <link name='iiwa_link_7'>
      <pose frame=''>0 0 1.261 0 0 0</pose>
      <inertial>
        <pose frame=''>0 0 0.001132 0 -0 0</pose>
        <mass>0.53</mass>
        <inertia>
          <ixx>0.000281321</ixx>
          <ixy>0</ixy>
          <ixz>0</ixz>
          <iyy>0.00181132</iyy>
          <iyz>-4.37114e-12</iyz>
          <izz>0.0019</izz>
        </inertia>
      </inertial>
      <collision name='iiwa_link_7_collision'>
        <pose frame=''>0 0 0 0 -0 0</pose>
        <geometry>
          <mesh>
            <scale>1 1 1</scale>
            <uri>model://kuka_robot_with_smaller_gripper/meshes/collision/link_7.dae</uri>
          </mesh>
        </geometry>
        <surface>
          <contact>
            <ode/>
          </contact>
          <friction>
            <ode>
              <mu>0.2</mu>
              <mu2>0.2</mu2>
            </ode>
          </friction>
        </surface>
      </collision>
      <collision name='iiwa_link_7_fixed_joint_lump__base_link_link_collision_1'>
        <pose frame=''>0 -0 0.025 0 -0 0</pose>
        <geometry>
          <mesh>
            <scale>0.75 1 1</scale>
            <uri>model://kuka_robot_with_smaller_gripper/meshes/collision/COL_base.dae</uri>
          </mesh>
        </geometry>
      </collision>
      <visual name='iiwa_link_7_visual'>
        <pose frame=''>0 0 0 0 -0 0</pose>
        <geometry>
          <mesh>
            <scale>1 1 1</scale>
            <uri>model://kuka_robot_with_smaller_gripper/meshes/visual/link_7.dae</uri>
          </mesh>
        </geometry>
        <material>
          <script>
            <name>Gazebo/Grey</name>
            <uri>file://media/materials/scripts/gazebo.material</uri>
          </script>
        </material>
      </visual>
      <visual name='iiwa_link_7_fixed_joint_lump__base_link_link_visual_1'>
        <pose frame=''>0 -0 0.025 0 -0 0</pose>
        <geometry>
          <mesh>
            <scale>0.75 1 1</scale>
            <uri>model://kuka_robot_with_smaller_gripper/meshes/visual/VIS_base.dae</uri>
          </mesh>
        </geometry>
      </visual>
      <gravity>1</gravity>
      <velocity_decay/>
    </link>
    <joint name='iiwa_joint_7' type='revolute'>
      <child>iiwa_link_7</child>
      <parent>iiwa_link_6</parent>
      <axis>
        <xyz>0 0 1</xyz>
        <limit>
          <lower>-3.05433</lower>
          <upper>3.05433</upper>
          <effort>300</effort>
          <velocity>10</velocity>
        </limit>
        <dynamics>
          <damping>0.5</damping>
          <friction>0</friction>
          <spring_reference>0</spring_reference>
          <spring_stiffness>0</spring_stiffness>
        </dynamics>
        <use_parent_model_frame>1</use_parent_model_frame>
      </axis>
      <physics>
        <provide_feedback>1</provide_feedback>
        <ode>
          <provide_feedback>1</provide_feedback>
          <limit>
            <cfm>0</cfm>
            <erp>0.2</erp>
          </limit>
        </ode>
      </physics>
                    <sensor name="force_torque" type="force_torque">
          <update_rate>30</update_rate>
        </sensor>
    </joint>
    <link name='gripper_left_link'>
      <pose frame=''>-0.085 -0 1.311 -3.14159 -0 1.5708</pose>
      <inertial>
        <pose frame=''>0 0 0 0 -0 0</pose>
        <mass>0.1</mass>
        <inertia>
          <ixx>0.0002</ixx>
          <ixy>0</ixy>
          <ixz>0</ixz>
          <iyy>0.000195</iyy>
          <iyz>0</iyz>
          <izz>2.1e-05</izz>
        </inertia>
      </inertial>
      <collision name='gripper_left_link_collision'>
        <pose frame=''>0 +0.025 -0.047 3.14159 0 1.5708</pose>
        <geometry>
          <mesh>
            <scale>1 1 0.666666667</scale>
            <uri>model://kuka_robot_with_smaller_gripper/meshes/collision/COL_gripper_left.dae</uri>
          </mesh>
        </geometry>
                    <!-- <surface>
                    <friction>
                        <ode>
                        <mu>10</mu>
                        <mu2>10</mu2>
                        <fdir1>1 1 1</fdir1>
                        </ode>
                    </friction>
                </surface>  -->
      </collision>
      <visual name='gripper_left_link_visual'>
        <pose frame=''>0 +0.025 -0.047 3.14159 0 1.5708</pose>
        <geometry>
          <mesh>
            <scale>1 1 0.666666667</scale>
            <uri>model://kuka_robot_with_smaller_gripper/meshes/visual/VIS_gripper_left.dae</uri>
          </mesh>
        </geometry>
      </visual>
    </link>
    <joint name='gripper_left_joint' type='prismatic'>
      <child>gripper_left_link</child>
      <parent>iiwa_link_7</parent>
      <pose>0 +0.025 0 0 0 0</pose>
      <axis>
        <xyz>1 -0 -0</xyz>
        <limit>
          <lower>0</lower>
          <upper>0.0454</upper>
          <effort>100</effort>
          <velocity>1</velocity>
        </limit>
        <dynamics>
          <damping>1</damping>
          <friction>0</friction>
          <spring_reference>0</spring_reference>
          <spring_stiffness>0</spring_stiffness>
        </dynamics>
        <use_parent_model_frame>1</use_parent_model_frame>
      </axis>
              <sensor name="force_torque" type="force_torque">
          <update_rate>30</update_rate>
        </sensor>
    </joint>
    <link name='gripper_right_link'>
      <pose frame=''>0.085 -0 1.311 -3.14159 0 -1.5708</pose>
      <inertial>
        <pose frame=''>0 0 0 0 -0 0</pose>
        <mass>0.1</mass>
        <inertia>
          <ixx>0.0002</ixx>
          <ixy>0</ixy>
          <ixz>0</ixz>
          <iyy>0.000195</iyy>
          <iyz>0</iyz>
          <izz>2.1e-05</izz>
        </inertia>
      </inertial>
      <collision name='gripper_right_link_collision'>
        <pose frame=''>0 +0.025 -0.047 3.14159 -0 -1.5708</pose>
        <geometry>
          <mesh>
            <scale>1 1 0.666666667</scale>
            <uri>model://kuka_robot_with_smaller_gripper/meshes/collision/COL_gripper_right.dae</uri>
          </mesh>
        </geometry>
      </collision>
      <visual name='gripper_right_link_visual'>
        <pose frame=''>0 +0.025 -0.047 3.14159 -0 -1.5708</pose>
        <geometry>
          <mesh>
            <scale>1 1 0.666666667</scale>
            <uri>model://kuka_robot_with_smaller_gripper/meshes/visual/VIS_gripper_right.dae</uri>
          </mesh>
        </geometry>
      </visual>
    </link>
    <joint name='gripper_right_joint' type='prismatic'>
      <child>gripper_right_link</child>
      <parent>iiwa_link_7</parent>
      <pose>0 +0.025 0 0 0 0</pose>
      <axis>
        <xyz>-1 -0 -0</xyz>
        <limit>
          <lower>0</lower>
          <upper>0.0454</upper>
          <effort>100</effort>
          <velocity>1</velocity>
        </limit>
        <dynamics>
          <damping>1</damping>
          <friction>0</friction>
          <spring_reference>0</spring_reference>
          <spring_stiffness>0</spring_stiffness>
        </dynamics>
        <use_parent_model_frame>1</use_parent_model_frame>
      </axis>
              <sensor name="force_torque" type="force_torque">
          <update_rate>30</update_rate>
        </sensor>
    </joint>
    <plugin name='ft_sensor' filename='libgazebo_ros_ft_sensor.so'>
      <updateRate>50.0</updateRate>
      <topicName>/iiwa/state/CartesianWrench</topicName>
      <jointName>iiwa_joint_7</jointName>
    </plugin>
    <plugin name='gazebo_grasp_fix' filename='libgazebo_grasp_fix.so'>
      <arm>
        <arm_name>iiwa</arm_name>
        <palm_link>iiwa_link_7</palm_link>
        <gripper_link>gripper_right_link</gripper_link>
        <gripper_link>gripper_left_link</gripper_link>
      </arm>
      <forces_angle_tolerance>100</forces_angle_tolerance>
      <update_rate>4</update_rate>
      <grip_count_threshold>4</grip_count_threshold>
      <max_grip_count>8</max_grip_count>
      <release_tolerance>0.005</release_tolerance>
      <disable_collisions_on_attach>0</disable_collisions_on_attach>
      <contact_topic>__default_topic__</contact_topic>
    </plugin>
    <static>0</static>
    <plugin name='gazebo_ros_control' filename='libgazebo_ros_control.so'>
      <robotNamespace>/iiwa</robotNamespace>
    </plugin>
  </model>
</sdf>
