<?xml version="1.0"?>
<robot name="rbkairos_kuka_iiwa_robotiq" xmlns:xacro="http://wiki.ros.org/xacro">
    <!-- Import rbkairos base -->
    <!-- <xacro:include filename="$(find rbkairos_description)/robots/rbkairos_base.urdf.xacro" />
    <xacro:rbkairos/> -->

    <!-- First we import all posible elements defined in the urdf.xacro files. All these elements are defined as macro:xacros -->
	<xacro:arg name="prefix" default="robot"/>
	<xacro:arg name="ros_planar_move_plugin" default="true"/>


    <!-- Import summit XL base elements -->
    <xacro:include filename="$(find rbkairos_description)/urdf/bases/rbkairos_base.urdf.xacro" />

    <xacro:rbkairos_base prefix="$(arg prefix)" publish_bf="true" hq="true"/>

   <xacro:if value="$(arg ros_planar_move_plugin)">
       <xacro:omni_steering prefix="$(arg prefix)" publish_tf="true"/>
   </xacro:if>

    <xacro:arg name="world_link" default="0"/>
    <xacro:if value="$(arg world_link)">
        <xacro:property name="base_link_name" value="world"/>
    </xacro:if>
    <xacro:unless value="$(arg world_link)">
        <xacro:property name="base_link_name" value="iiwa_base_link"/>
    </xacro:unless>

    <xacro:arg name="robot_ns" default="iiwa"/>
    <xacro:if value="${'$(arg robot_ns)' != '!'}">
        <xacro:property name="robot_namespace" value="$(arg robot_ns)::"/>
    </xacro:if>
    <xacro:unless value="${'$(arg robot_ns)' != '!'}">
        <xacro:property name="robot_namespace" value=""/>
    </xacro:unless>

    <xacro:property name="joint_damping" value="0.5"/>
    <xacro:property name="joint_friction" value="0.0"/>
    <xacro:property name="joint_spring_ref" value="0.0"/>
    <xacro:property name="joint_spring_stiffness" value="0.0"/>
    <xacro:property name="joint_stop_dissipation" value="0.0"/>

    <material name="Black">
        <color rgba="0.0 0.0 0.0 1.0" />
    </material>
    <material name="Blue">
        <color rgba="0.0 0.0 0.8 1.0" />
    </material>
    <material name="Green">
        <color rgba="0.0 0.8 0.0 1.0" />
    </material>
    <material name="Grey">
        <color rgba="0.4 0.4 0.4 1.0" />
    </material>
    <material name="Orange">
        <color rgba="1.0 0.423529411765 0.0392156862745 1.0" />
    </material>
    <material name="Brown">
        <color rgba="0.870588235294 0.811764705882 0.764705882353 1.0" />
    </material>
    <material name="Red">
        <color rgba="0.8 0.0 0.0 1.0" />
    </material>
    <material name="White">
        <color rgba="1.0 1.0 1.0 1.0" />
    </material>
    <!-- World. Affix this on spawn -->
    <!-- <link name="${robot_namespace}${base_link_name}" /> -->
    <!--joint between base and link_0-->
    <joint name="base_iiwa_joint" type="revolute">
        <origin rpy="0 0 0" xyz="0 0 0.38" />
        <parent link="$(arg prefix)base_link" />
        <child link="${robot_namespace}iiwa_link_0" />
        <limit lower="0" upper="0" effort="0" velocity="0" />
    </joint>
    <link name="${robot_namespace}iiwa_link_0">
        
        <inertial>
            <origin rpy="0 0 0" xyz="-0.1 0 0.07" />
            <mass value="5" />
            <inertia ixx="0.05" ixy="0" ixz="0" iyy="0.06" iyz="0" izz="0.03" />
        </inertial>

        <visual>
            <origin rpy="0 0 0" xyz="0 0 0" />
            <geometry>
                <mesh filename="package://cobotics_kuka_iiwa/meshes/visual/link_0.stl" />
            </geometry>
            <material name="Grey" />
        </visual>
        <collision>
            <origin rpy="0 0 0" xyz="0 0 0" />
            <geometry>
                <mesh filename="package://cobotics_kuka_iiwa/meshes/collision/link_0.stl" />
            </geometry>
            <material name="Grey" />
        </collision>
        <self_collision_checking>
            <origin rpy="0 0 0" xyz="0 0 0" />
            <geometry>
                <capsule length="0.25" radius="0.15" />
            </geometry>
        </self_collision_checking>
    </link>
    <!-- joint between link_0 and link_1 -->
    <joint name="iiwa_joint_1" type="revolute">
        <parent link="${robot_namespace}iiwa_link_0" />
        <child link="${robot_namespace}iiwa_link_1" />
        <origin rpy="0 0 0" xyz="0 0 0.1575" />
        <axis xyz="0 0 1" />
        <limit effort="300" lower="-2.96705972839" upper="2.96705972839" velocity="10" />
        <safety_controller k_position="100" k_velocity="2" soft_lower_limit="-2.93215314335" soft_upper_limit="2.93215314335" />
        <dynamics damping="${joint_damping}" friction="${joint_friction}" />
    </joint>
    <link name="${robot_namespace}iiwa_link_1">
        
        <inertial>
            <origin rpy="0 0 0" xyz="0 -0.03 0.12" />
            <mass value="4" />
            <inertia ixx="0.1" ixy="0" ixz="0" iyy="0.09" iyz="0" izz="0.02" />
        </inertial>

        <visual>
            <origin rpy="0 0 0" xyz="0 0 0" />
            <geometry>
                <mesh filename="package://cobotics_kuka_iiwa/meshes/visual/link_1.stl" />
            </geometry>
            <material name="Orange" />
        </visual>
        <collision>
            <origin rpy="0 0 0" xyz="0 0 0" />
            <geometry>
                <mesh filename="package://cobotics_kuka_iiwa/meshes/collision/link_1.stl" />
            </geometry>
            <material name="Orange" />
        </collision>
    </link>
    <!-- joint between link_1 and link_2 -->
    <joint name="iiwa_joint_2" type="revolute">
        <parent link="${robot_namespace}iiwa_link_1" />
        <child link="${robot_namespace}iiwa_link_2" />
        <origin rpy="1.57079632679   0 3.14159265359" xyz="0 0 0.2025" />
        <axis xyz="0 0 1" />
        <limit effort="300" lower="-2.09439510239" upper="2.09439510239" velocity="10" />
        <safety_controller k_position="100" k_velocity="2" soft_lower_limit="-2.05948851735" soft_upper_limit="2.05948851735" />
        <dynamics damping="${joint_damping}" friction="${joint_friction}" />
    </joint>
    <link name="${robot_namespace}iiwa_link_2">
        
        <inertial>
            <origin rpy="0 0 0" xyz="0.0003 0.059 0.042" />
            <mass value="0.4" />
            <inertia ixx="0.005" ixy="0" ixz="0" iyy="0.0018" iyz="0" izz="0.0044" />
        </inertial>

        <visual>
            <origin rpy="0 0 0" xyz="0 0 0" />
            <geometry>
                <mesh filename="package://cobotics_kuka_iiwa/meshes/visual/link_2.stl" />
            </geometry>
            <material name="Orange" />
        </visual>
        <collision>
            <origin rpy="0 0 0" xyz="0 0 0" />
            <geometry>
                <mesh filename="package://cobotics_kuka_iiwa/meshes/collision/link_2.stl" />
            </geometry>
            <material name="Orange" />
        </collision>
    </link>
    <!-- joint between link_2 and link_3 -->
    <joint name="iiwa_joint_3" type="revolute">
        <parent link="${robot_namespace}iiwa_link_2" />
        <child link="${robot_namespace}iiwa_link_3" />
        <origin rpy="1.57079632679 0 3.14159265359" xyz="0 0.2045 0" />
        <axis xyz="0 0 1" />
        <limit effort="300" lower="-2.96705972839" upper="2.96705972839" velocity="10" />
        <safety_controller k_position="100" k_velocity="2" soft_lower_limit="-2.93215314335" soft_upper_limit="2.93215314335" />
        <dynamics damping="${joint_damping}" friction="${joint_friction}" />
    </joint>
    <link name="${robot_namespace}iiwa_link_3">
        
        <inertial>
            <origin rpy="0 0 0" xyz="0 0.03 0.13" />
            <mass value="0.3" />
            <inertia ixx="0.008" ixy="0" ixz="0" iyy="0.0075" iyz="0" izz="0.001" />
        </inertial>

        <visual>
            <origin rpy="0 0 0" xyz="0 0 0" />
            <geometry>
                <mesh filename="package://cobotics_kuka_iiwa/meshes/visual/link_3.stl" />
            </geometry>
            <material name="Orange" />
        </visual>
        <collision>
            <origin rpy="0 0 0" xyz="0 0 0" />
            <geometry>
                <mesh filename="package://cobotics_kuka_iiwa/meshes/collision/link_3.stl" />
            </geometry>
            <material name="Orange" />
        </collision>
    </link>
    <!-- joint between link_3 and link_4 -->
    <joint name="iiwa_joint_4" type="revolute">
        <parent link="${robot_namespace}iiwa_link_3" />
        <child link="${robot_namespace}iiwa_link_4" />
        <origin rpy="1.57079632679 0 0" xyz="0 0 0.2155" />
        <axis xyz="0 0 1" />
        <limit effort="300" lower="-2.09439510239" upper="2.09439510239" velocity="10" />
        <safety_controller k_position="100" k_velocity="2" soft_lower_limit="-2.05948851735" soft_upper_limit="2.05948851735" />
        <dynamics damping="${joint_damping}" friction="${joint_friction}" />
    </joint>
    <link name="${robot_namespace}iiwa_link_4">
        
        <inertial>
            <origin rpy="0 0 0" xyz="0 0.067 0.034" />
            <mass value="0.27" />
            <inertia ixx="0.003" ixy="0" ixz="0" iyy="0.001" iyz="0" izz="0.0029" />
        </inertial>

        <visual>
            <origin rpy="0 0 0" xyz="0 0 0" />
            <geometry>
                <mesh filename="package://cobotics_kuka_iiwa/meshes/visual/link_4.stl" />
            </geometry>
            <material name="Orange" />
        </visual>
        <collision>
            <origin rpy="0 0 0" xyz="0 0 0" />
            <geometry>
                <mesh filename="package://cobotics_kuka_iiwa/meshes/collision/link_4.stl" />
            </geometry>
            <material name="Orange" />
        </collision>
    </link>
    <!-- joint between link_4 and link_5 -->
    <joint name="iiwa_joint_5" type="revolute">
        <parent link="${robot_namespace}iiwa_link_4" />
        <child link="${robot_namespace}iiwa_link_5" />
        <origin rpy="-1.57079632679 3.14159265359 0" xyz="0 0.1845 0" />
        <axis xyz="0 0 1" />
        <limit effort="300" lower="-2.96705972839" upper="2.96705972839" velocity="10" />
        <safety_controller k_position="100" k_velocity="2" soft_lower_limit="-2.93215314335" soft_upper_limit="2.93215314335" />
        <dynamics damping="${joint_damping}" friction="${joint_friction}" />
    </joint>
    <link name="${robot_namespace}iiwa_link_5">
        
        <inertial>
            <origin rpy="0 0 0" xyz="0.0001 0.021 0.076" />
            <mass value="0.17" />
            <inertia ixx="0.002" ixy="0" ixz="0" iyy="0.0018" iyz="0" izz="0.0005" />
        </inertial>

        <visual>
            <origin rpy="0 0 0" xyz="0 0 0" />
            <geometry>
                <mesh filename="package://cobotics_kuka_iiwa/meshes/visual/link_5.stl" />
            </geometry>
            <material name="Orange" />
        </visual>
        <collision>
            <origin rpy="0 0 0" xyz="0 0 0" />
            <geometry>
                <mesh filename="package://cobotics_kuka_iiwa/meshes/collision/link_5.stl" />
            </geometry>
            <material name="Orange" />
        </collision>
    </link>
    <!-- joint between link_5 and link_6 -->
    <joint name="iiwa_joint_6" type="revolute">
        <parent link="${robot_namespace}iiwa_link_5" />
        <child link="${robot_namespace}iiwa_link_6" />
        <origin rpy="1.57079632679 0 0" xyz="0 0 0.2155" />
        <axis xyz="0 0 1" />
        <limit effort="300" lower="-2.09439510239" upper="2.09439510239" velocity="10" />
        <safety_controller k_position="100" k_velocity="2" soft_lower_limit="-2.05948851735" soft_upper_limit="2.05948851735" />
        <dynamics damping="${joint_damping}" friction="${joint_friction}" />
    </joint>
    <link name="${robot_namespace}iiwa_link_6">
        
        <inertial>
            <origin rpy="0 0 0" xyz="0 0.0006 0.0004" />
            <mass value="0.18" />
            <inertia ixx="0.0005" ixy="0" ixz="0" iyy="0.00036" iyz="0" izz="0.00047" />
        </inertial>

        <visual>
            <origin rpy="0 0 0" xyz="0 0 0" />
            <geometry>
                <mesh filename="package://cobotics_kuka_iiwa/meshes/visual/link_6.stl" />
            </geometry>
            <material name="Orange" />
        </visual>
        <collision>
            <origin rpy="0 0 0" xyz="0 0 0" />
            <geometry>
                <mesh filename="package://cobotics_kuka_iiwa/meshes/collision/link_6.stl" />
            </geometry>
            <material name="Orange" />
        </collision>
    </link>
    <!-- joint between link_6 and link_7 -->
    <joint name="iiwa_joint_7" type="revolute">
        <parent link="${robot_namespace}iiwa_link_6" />
        <child link="${robot_namespace}iiwa_link_7" />
        <origin rpy="-1.57079632679 3.14159265359 0" xyz="0 0.081 0" />
        <axis xyz="0 0 1" />
        <limit effort="300" lower="-3.05432619099" upper="3.05432619099" velocity="10" />
        <safety_controller k_position="100" k_velocity="2" soft_lower_limit="-3.01941960595" soft_upper_limit="3.01941960595" />
        <dynamics damping="${joint_damping}" friction="${joint_friction}" />
    </joint>
    <link name="${robot_namespace}iiwa_link_7">
        
        <inertial>
            <origin rpy="0 0 0" xyz="0 0 0.02" />
            <mass value="0.03" />
            <inertia ixx="0.0001" ixy="0" ixz="0" iyy="0.0001" iyz="0" izz="0.0001" />
        </inertial>

        <visual>
            <origin rpy="0 0 0" xyz="0 0 0" />
            <geometry>
                <mesh filename="package://cobotics_kuka_iiwa/meshes/visual/link_7.stl" />
            </geometry>
            <material name="Grey" />
        </visual>
        <collision>
            <origin rpy="0 0 0" xyz="0 0 0" />
            <geometry>
                <mesh filename="package://cobotics_kuka_iiwa/meshes/collision/link_7.stl" />
            </geometry>
            <material name="Grey" />
        </collision>
    </link>
    <joint name="iiwa_joint_ee" type="fixed">
        <parent link="${robot_namespace}iiwa_link_7" />
        <child link="${robot_namespace}iiwa_link_ee" />
        <origin rpy="0 0 0" xyz="0 0 0.045" />
    </joint>
    <link name="${robot_namespace}iiwa_link_ee" />

    <gazebo reference="iiwa_joint_1">
        <dynamics>
            <spring_reference>${joint_spring_ref}</spring_reference>
            <spring_stiffness>${joint_spring_stiffness}</spring_stiffness>
        </dynamics>
    </gazebo>
    <gazebo reference="iiwa_joint_2">
        <dynamics>
            <spring_reference>${joint_spring_ref}</spring_reference>
            <spring_stiffness>${joint_spring_stiffness}</spring_stiffness>
        </dynamics>
    </gazebo>
    <gazebo reference="iiwa_joint_3">
        <dynamics>
            <spring_reference>${joint_spring_ref}</spring_reference>
            <spring_stiffness>${joint_spring_stiffness}</spring_stiffness>
        </dynamics>
    </gazebo>
    <gazebo reference="iiwa_joint_4">
        <dynamics>
            <spring_reference>${joint_spring_ref}</spring_reference>
            <spring_stiffness>${joint_spring_stiffness}</spring_stiffness>
        </dynamics>
    </gazebo>
    <gazebo reference="iiwa_joint_5">
        <dynamics>
            <spring_reference>${joint_spring_ref}</spring_reference>
            <spring_stiffness>${joint_spring_stiffness}</spring_stiffness>
        </dynamics>
    </gazebo>
    <gazebo reference="iiwa_joint_6">
        <dynamics>
            <spring_reference>${joint_spring_ref}</spring_reference>
            <spring_stiffness>${joint_spring_stiffness}</spring_stiffness>
        </dynamics>
    </gazebo>
    <gazebo reference="iiwa_joint_7">
        <dynamics>
            <spring_reference>${joint_spring_ref}</spring_reference>
            <spring_stiffness>${joint_spring_stiffness}</spring_stiffness>
        </dynamics>
        <!-- Enable the Joint Feedback -->
        <provideFeedback>true</provideFeedback>
    </gazebo>
    
    <!-- The ft_sensor plugin -->
    <gazebo>
        <plugin filename="libgazebo_ros_ft_sensor.so" name="ft_sensor">
            <updateRate>50.0</updateRate>
            <topicName>/iiwa/state/CartesianWrench</topicName>
            <jointName>iiwa_joint_7</jointName>
        </plugin>
        <plugin name="gazebo_grasp_fix" filename="libgazebo_grasp_fix.so">
            <arm>
                <arm_name>iiwa</arm_name>
                <palm_link>${robot_namespace}iiwa_link_7</palm_link>
                <gripper_link>${robot_namespace}gripper_right_link</gripper_link>
                <gripper_link>${robot_namespace}gripper_left_link</gripper_link>
            </arm>
            <forces_angle_tolerance>100</forces_angle_tolerance>
            <update_rate>4</update_rate>
            <grip_count_threshold>4</grip_count_threshold>
            <max_grip_count>8</max_grip_count>
            <release_tolerance>0.005</release_tolerance>
            <disable_collisions_on_attach>false</disable_collisions_on_attach>
            <contact_topic>__default_topic__</contact_topic>
        </plugin>
    </gazebo>
    <!-- Load Gazebo lib and set the robot namespace -->
    <gazebo>
        <plugin filename="libgazebo_ros_control.so" name="gazebo_ros_control">
	        <robotNamespace>/$(arg robot_ns)</robotNamespace>
            <robotSimType>IIWARobotHWSim</robotSimType>
        </plugin>
    </gazebo>
    <!-- Link0 -->
    <gazebo reference="${robot_namespace}iiwa_link_0">
        <material>Gazebo/Grey</material>
        <mu1>0.2</mu1>
        <mu2>0.2</mu2>
    </gazebo>
    <!-- Link1 -->
    <gazebo reference="${robot_namespace}iiwa_link_1">
        <material>Gazebo/Orange</material>
        <mu1>0.2</mu1>
        <mu2>0.2</mu2>
    </gazebo>
    <!-- Link2 -->
    <gazebo reference="${robot_namespace}iiwa_link_2">
        <material>Gazebo/Orange</material>
        <mu1>0.2</mu1>
        <mu2>0.2</mu2>
    </gazebo>
    <!-- Link3 -->
    <gazebo reference="${robot_namespace}iiwa_link_3">
        <material>Gazebo/Orange</material>
        <mu1>0.2</mu1>
        <mu2>0.2</mu2>
    </gazebo>
    <!-- Link4 -->
    <gazebo reference="${robot_namespace}iiwa_link_4">
        <material>Gazebo/Orange</material>
        <mu1>0.2</mu1>
        <mu2>0.2</mu2>
    </gazebo>
    <!-- Link5 -->
    <gazebo reference="${robot_namespace}iiwa_link_5">
        <material>Gazebo/Orange</material>
        <mu1>0.2</mu1>
        <mu2>0.2</mu2>
    </gazebo>
    <!-- Link6 -->
    <gazebo reference="${robot_namespace}iiwa_link_6">
        <material>Gazebo/Orange</material>
        <mu1>0.2</mu1>
        <mu2>0.2</mu2>
    </gazebo>
    <!-- Link7 -->
    <gazebo reference="${robot_namespace}iiwa_link_7">
        <material>Gazebo/Grey</material>
        <mu1>0.2</mu1>
        <mu2>0.2</mu2>
    </gazebo>
    <transmission name="iiwa_tran_1">
        <robotNamespace>/iiwa</robotNamespace>
        <type>transmission_interface/SimpleTransmission</type>
        <joint name="iiwa_joint_1">
            <hardwareInterface>PositionJointInterface</hardwareInterface>
            <!--<hardwareInterface>PositionJointInterface</hardwareInterface>-->
        </joint>
        <actuator name="iiwa_motor_1">
            <hardwareInterface>PositionJointInterface</hardwareInterface>
            <!--<hardwareInterface>hardware_interface/PositionJointInterface</hardwareInterface>-->
            <mechanicalReduction>1</mechanicalReduction>
        </actuator>
    </transmission>
    <transmission name="iiwa_tran_2">
        <robotNamespace>/iiwa</robotNamespace>
        <type>transmission_interface/SimpleTransmission</type>
        <joint name="iiwa_joint_2">
            <hardwareInterface>PositionJointInterface</hardwareInterface>
            <!--<hardwareInterface>hardware_interface/PositionJointInterface</hardwareInterface>-->
        </joint>
        <actuator name="iiwa_motor_2">
            <hardwareInterface>PositionJointInterface</hardwareInterface>
            <!--<hardwareInterface>hardware_interface/PositionJointInterface</hardwareInterface>-->
            <mechanicalReduction>1</mechanicalReduction>
        </actuator>
    </transmission>
    <transmission name="iiwa_tran_3">
        <robotNamespace>/iiwa</robotNamespace>
        <type>transmission_interface/SimpleTransmission</type>
        <joint name="iiwa_joint_3">
            <hardwareInterface>PositionJointInterface</hardwareInterface>
            <!--<hardwareInterface>hardware_interface/PositionJointInterface</hardwareInterface>-->
        </joint>
        <actuator name="iiwa_motor_3">
            <hardwareInterface>PositionJointInterface</hardwareInterface>
            <!--<hardwareInterface>hardware_interface/PositionJointInterface</hardwareInterface>-->
            <mechanicalReduction>1</mechanicalReduction>
        </actuator>
    </transmission>
    <transmission name="iiwa_tran_4">
        <robotNamespace>/iiwa</robotNamespace>
        <type>transmission_interface/SimpleTransmission</type>
        <joint name="iiwa_joint_4">
            <hardwareInterface>PositionJointInterface</hardwareInterface>
            <!--<hardwareInterface>hardware_interface/PositionJointInterface</hardwareInterface>-->
        </joint>
        <actuator name="iiwa_motor_4">
            <hardwareInterface>PositionJointInterface</hardwareInterface>
            <!--<hardwareInterface>hardware_interface/PositionJointInterface</hardwareInterface>-->
            <mechanicalReduction>1</mechanicalReduction>
        </actuator>
    </transmission>
    <transmission name="iiwa_tran_5">
        <robotNamespace>/iiwa</robotNamespace>
        <type>transmission_interface/SimpleTransmission</type>
        <joint name="iiwa_joint_5">
            <hardwareInterface>PositionJointInterface</hardwareInterface>
            <!--<hardwareInterface>hardware_interface/PositionJointInterface</hardwareInterface>-->
        </joint>
        <actuator name="iiwa_motor_5">
            <hardwareInterface>PositionJointInterface</hardwareInterface>
            <!--<hardwareInterface>hardware_interface/PositionJointInterface</hardwareInterface>-->
            <mechanicalReduction>1</mechanicalReduction>
        </actuator>
    </transmission>
    <transmission name="iiwa_tran_6">
        <robotNamespace>/iiwa</robotNamespace>
        <type>transmission_interface/SimpleTransmission</type>
        <joint name="iiwa_joint_6">
            <hardwareInterface>PositionJointInterface</hardwareInterface>
            <!--<hardwareInterface>hardware_interface/PositionJointInterface</hardwareInterface>-->
        </joint>
        <actuator name="iiwa_motor_6">
            <hardwareInterface>PositionJointInterface</hardwareInterface>
            <!--<hardwareInterface>hardware_interface/PositionJointInterface</hardwareInterface>-->
            <mechanicalReduction>1</mechanicalReduction>
        </actuator>
    </transmission>
    <transmission name="iiwa_tran_7">
        <robotNamespace>/iiwa</robotNamespace>
        <type>transmission_interface/SimpleTransmission</type>
        <joint name="iiwa_joint_7">
            <hardwareInterface>PositionJointInterface</hardwareInterface>
            <!--<hardwareInterface>hardware_interface/PositionJointInterface</hardwareInterface>-->
        </joint>
        <actuator name="iiwa_motor_7">
            <hardwareInterface>PositionJointInterface</hardwareInterface>
            <!--<hardwareInterface>hardware_interface/PositionJointInterface</hardwareInterface>-->
            <mechanicalReduction>1</mechanicalReduction>
        </actuator>
    </transmission>
    <joint name="base_link_joint" type="fixed">
        <origin rpy="1.5707963705062866 -0 -0" xyz="0 0 0" />
        <!-- <origin rpy="0 -0 0" xyz="0 0 0" /> -->
        <parent link="${robot_namespace}iiwa_link_ee" />
        <child link="${robot_namespace}palm" />
        <axis xyz="0 0 1" />
        <calibration falling="0.0" reference_position="0.0" rising="0.0" />
        <dynamics damping="1.0" />
        <limit effort="100.0" lower="1.0" upper="1.0" velocity="1.0" />
    </joint>

    <xacro:include filename="$(find robotiq_3f_gripper_visualization)/cfg/robotiq-3f-gripper_articulated_macro.xacro" />
    <xacro:robotiq-3f-gripper_articulated prefix="${robot_namespace}"/>

    <transmission name="palm_finger_1_tran">
        <robotNamespace>/iiwa</robotNamespace>
        <type>transmission_interface/SimpleTransmission</type>
        <joint name="palm_finger_1_joint">
            <hardwareInterface>EffortJointInterface</hardwareInterface>
            <!--<hardwareInterface>hardware_interface/PositionJointInterface</hardwareInterface>-->
        </joint>
        <actuator name="palm_finger_1_motor">
            <hardwareInterface>EffortJointInterface</hardwareInterface>
            <!--<hardwareInterface>hardware_interface/PositionJointInterface</hardwareInterface>-->
            <mechanicalReduction>1</mechanicalReduction>
        </actuator>
    </transmission>
    <transmission name="palm_finger_2_tran">
        <robotNamespace>/iiwa</robotNamespace>
        <type>transmission_interface/SimpleTransmission</type>
        <joint name="palm_finger_2_joint">
            <hardwareInterface>EffortJointInterface</hardwareInterface>
            <!--<hardwareInterface>hardware_interface/PositionJointInterface</hardwareInterface>-->
        </joint>
        <actuator name="palm_finger_2_motor">
            <hardwareInterface>EffortJointInterface</hardwareInterface>
            <!--<hardwareInterface>hardware_interface/PositionJointInterface</hardwareInterface>-->
            <mechanicalReduction>1</mechanicalReduction>
        </actuator>
    </transmission>

    <transmission name="finger_1_tran_1">
        <robotNamespace>/iiwa</robotNamespace>
        <type>transmission_interface/SimpleTransmission</type>
        <joint name="finger_1_joint_1">
            <hardwareInterface>EffortJointInterface</hardwareInterface>
            <!--<hardwareInterface>hardware_interface/PositionJointInterface</hardwareInterface>-->
        </joint>
        <actuator name="finger_1_motor_1">
            <hardwareInterface>EffortJointInterface</hardwareInterface>
            <!--<hardwareInterface>hardware_interface/PositionJointInterface</hardwareInterface>-->
            <mechanicalReduction>1</mechanicalReduction>
        </actuator>
    </transmission>
    <transmission name="finger_2_tran_1">
        <robotNamespace>/iiwa</robotNamespace>
        <type>transmission_interface/SimpleTransmission</type>
        <joint name="finger_2_joint_1">
            <hardwareInterface>EffortJointInterface</hardwareInterface>
            <!--<hardwareInterface>hardware_interface/PositionJointInterface</hardwareInterface>-->
        </joint>
        <actuator name="finger_2_motor_1">
            <hardwareInterface>EffortJointInterface</hardwareInterface>
            <!--<hardwareInterface>hardware_interface/PositionJointInterface</hardwareInterface>-->
            <mechanicalReduction>1</mechanicalReduction>
        </actuator>
    </transmission>
    <transmission name="finger_middle_tran_1">
        <robotNamespace>/iiwa</robotNamespace>
        <type>transmission_interface/SimpleTransmission</type>
        <joint name="finger_middle_joint_1">
            <hardwareInterface>EffortJointInterface</hardwareInterface>
            <!--<hardwareInterface>hardware_interface/PositionJointInterface</hardwareInterface>-->
        </joint>
        <actuator name="finger_middle_motor_1">
            <hardwareInterface>EffortJointInterface</hardwareInterface>
            <!--<hardwareInterface>hardware_interface/PositionJointInterface</hardwareInterface>-->
            <mechanicalReduction>1</mechanicalReduction>
        </actuator>
    </transmission>

    <transmission name="finger_1_tran_2">
        <robotNamespace>/iiwa</robotNamespace>
        <type>transmission_interface/SimpleTransmission</type>
        <joint name="finger_1_joint_2">
            <hardwareInterface>EffortJointInterface</hardwareInterface>
            <!--<hardwareInterface>hardware_interface/PositionJointInterface</hardwareInterface>-->
        </joint>
        <actuator name="finger_1_motor_2">
            <hardwareInterface>EffortJointInterface</hardwareInterface>
            <!--<hardwareInterface>hardware_interface/PositionJointInterface</hardwareInterface>-->
            <mechanicalReduction>1</mechanicalReduction>
        </actuator>
    </transmission>
    <transmission name="finger_2_tran_2">
        <robotNamespace>/iiwa</robotNamespace>
        <type>transmission_interface/SimpleTransmission</type>
        <joint name="finger_2_joint_2">
            <hardwareInterface>EffortJointInterface</hardwareInterface>
            <!--<hardwareInterface>hardware_interface/PositionJointInterface</hardwareInterface>-->
        </joint>
        <actuator name="finger_2_motor_2">
            <hardwareInterface>EffortJointInterface</hardwareInterface>
            <!--<hardwareInterface>hardware_interface/PositionJointInterface</hardwareInterface>-->
            <mechanicalReduction>1</mechanicalReduction>
        </actuator>
    </transmission>
    <transmission name="finger_middle_tran_2">
        <robotNamespace>/iiwa</robotNamespace>
        <type>transmission_interface/SimpleTransmission</type>
        <joint name="finger_middle_joint_2">
            <hardwareInterface>EffortJointInterface</hardwareInterface>
            <!--<hardwareInterface>hardware_interface/PositionJointInterface</hardwareInterface>-->
        </joint>
        <actuator name="finger_middle_motor_2">
            <hardwareInterface>EffortJointInterface</hardwareInterface>
            <!--<hardwareInterface>hardware_interface/PositionJointInterface</hardwareInterface>-->
            <mechanicalReduction>1</mechanicalReduction>
        </actuator>
    </transmission>

    <transmission name="finger_1_tran_3">
        <robotNamespace>/iiwa</robotNamespace>
        <type>transmission_interface/SimpleTransmission</type>
        <joint name="finger_1_joint_3">
            <hardwareInterface>EffortJointInterface</hardwareInterface>
            <!--<hardwareInterface>hardware_interface/PositionJointInterface</hardwareInterface>-->
        </joint>
        <actuator name="finger_1_motor_3">
            <hardwareInterface>EffortJointInterface</hardwareInterface>
            <!--<hardwareInterface>hardware_interface/PositionJointInterface</hardwareInterface>-->
            <mechanicalReduction>1</mechanicalReduction>
        </actuator>
    </transmission>
    <transmission name="finger_2_tran_3">
        <robotNamespace>/iiwa</robotNamespace>
        <type>transmission_interface/SimpleTransmission</type>
        <joint name="finger_2_joint_3">
            <hardwareInterface>EffortJointInterface</hardwareInterface>
            <!--<hardwareInterface>hardware_interface/PositionJointInterface</hardwareInterface>-->
        </joint>
        <actuator name="finger_2_motor_3">
            <hardwareInterface>EffortJointInterface</hardwareInterface>
            <!--<hardwareInterface>hardware_interface/PositionJointInterface</hardwareInterface>-->
            <mechanicalReduction>1</mechanicalReduction>
        </actuator>
    </transmission>
    <transmission name="finger_middle_tran_3">
        <robotNamespace>/iiwa</robotNamespace>
        <type>transmission_interface/SimpleTransmission</type>
        <joint name="finger_middle_joint_3">
            <hardwareInterface>EffortJointInterface</hardwareInterface>
            <!--<hardwareInterface>hardware_interface/PositionJointInterface</hardwareInterface>-->
        </joint>
        <actuator name="finger_middle_motor_3">
            <hardwareInterface>EffortJointInterface</hardwareInterface>
            <!--<hardwareInterface>hardware_interface/PositionJointInterface</hardwareInterface>-->
            <mechanicalReduction>1</mechanicalReduction>
        </actuator>
    </transmission>

    <gazebo>
        <static>false</static>
        <plugin name="ROSRobotPosePublisher" filename="ROSRobotPosePublisherPlugin.so">
            <ROSFrameID>rbkairos::base_link</ROSFrameID>
        </plugin>
    </gazebo>
</robot>
